Workbook
Name Deploy: '[1]Phase 1 DPSD'!$B$25:$B$29
Name Design: '[1]Phase 1 DPSD'!$B$10:$B$21
Name FW: '[2]EV WORKSHEET'!$I$20
Name PFS: '[1]Phase 1 DPSD'!$B$6:$B$8
Name Validate: '[1]Phase 1 DPSD'!$B$23
Name VSTS_ca0d9927_1768_40fa_bb5c_3f5eb02544bc_2: #REF!
Name Hourly_Rate: EVM!$D$5
Name VSTS_ca0d9927_1768_40fa_bb5c_3f5eb02544bc_1: #REF!
Name VSTS_ca0d9927_1768_40fa_bb5c_3f5eb02544bc_80: #REF!
Name Hourly_Rate: EVM!$D$5
Name VSTS_ca0d9927_1768_40fa_bb5c_3f5eb02544bc_1: #REF!
Name FW: 'EV WORKSHEET'!$I$20
Name Week: 'EV WORKSHEET'!$L$14
Name VSTS_ca0d9927_1768_40fa_bb5c_3f5eb02544bc_25: #REF!
Name VSTS_ca0d9927_1768_40fa_bb5c_3f5eb02544bc_2: #REF!
Name VSTS_ca0d9927_1768_40fa_bb5c_3f5eb02544bc_n3: #REF!
Name VSTS_ca0d9927_1768_40fa_bb5c_3f5eb02544bc_n3: #REF!
Name VSTS_ca0d9927_1768_40fa_bb5c_3f5eb02544bc_10008: #REF!
Name VSTS_ca0d9927_1768_40fa_bb5c_3f5eb02544bc_24: #REF!
Name VSTS_ca0d9927_1768_40fa_bb5c_3f5eb02544bc_10018: #REF!
Name VSTS_ca0d9927_1768_40fa_bb5c_3f5eb02544bc_24: #REF!
Name VSTS_ca0d9927_1768_40fa_bb5c_3f5eb02544bc_80: #REF!
Name VSTS_ca0d9927_1768_40fa_bb5c_3f5eb02544bc_25: #REF!
Name VSTS_ca0d9927_1768_40fa_bb5c_3f5eb02544bc_10008: #REF!
Name VSTS_ca0d9927_1768_40fa_bb5c_3f5eb02544bc_10018: #REF!

Sheet Resource Plan - Approved
A3: Resource Plan
E4: 43675 | F4: =E4+7 -> 43682 | G4: =F4+7 -> 43689 | H4: =G4+7 -> 43696 | I4: =H4+7 -> 43703 | J4: =I4+7 -> 43710 | K4: =J4+7 -> 43717 | L4: =K4+7 -> 43724 | M4: =L4+7 -> 43731 | ... Z4: =Y4+7 -> 43822
E5: DEV | F5: DEV | G5: UAT | H5: UAT | I5: TTT | J5: REL | K5: SS | L5: SS | M5: SS | N5: SS | O5: PFS11 | P5: PFS12 | Q5: PFS13 | R5: PFS14 | S5: PFS15 | T5: WK22 | U5: WK23 | V5: WK24 | W5: WK25 | X5: WK26 | Y5: WK27 | Z5: WK28 | AA5: Total Hours | AB5: Total Expense
A6: Resource | B6: Type | C6: Role | D6: Rate | E6: Planned | F6: Planned | G6: Planned | H6: Planned | I6: Planned | J6: Planned | K6: Planned | L6: Planned | M6: Planned | N6: Planned | O6: Planned | P6: Planned | Q6: Planned | R6: Planned | S6: Planned | T6: Planned | U6: Planned | V6: Planned | W6: Planned | X6: Planned | Y6: Planned | Z6: Planned
A7: Oscar Sadder | B7: OnShore | C7: PD | D7: 165 | E7: 2 | F7: 2 | G7: 2 | H7: 2 | I7: 2 | J7: 2 | K7: 2 | L7: 2 | M7: 2 | N7: 2 | AA7: =SUM(E7:T7) -> 20 | AB7: =AA7*Hourly_Rate -> 3300
A8: Agustin Galindo | B8: OnShore | C8: PM | D8: 165 | E8: 10 | F8: 10 | G8: 10 | H8: 10 | I8: 10 | J8: 10 | K8: 10 | L8: 10 | M8: 10 | N8: 10 | AA8: =SUM(E8:T8) -> 100 | AB8: =AA8*Hourly_Rate -> 16500
A9: Scott Soulgares | B9: OnShore | C9: BA | D9: 165 | E9: 8 | F9: 20 | G9: 10 | H9: 10 | I9: 10 | J9: 10 | K9: 10 | L9: 10 | M9: 10 | N9: 10 | AA9: =SUM(E9:T9) -> 108 | AB9: =AA9*Hourly_Rate -> 17820
A10: Vladimir Belomenstnov | B10: OnShore | C10: DEV | D10: 165 | E10: 10 | F10: 20 | G10: 10 | H10: 10 | I10: 10 | J10: 10 | K10: 10 | L10: 10 | M10: 10 | N10: 10 | AA10: =SUM(E10:T10) -> 110 | AB10: =AA10*Hourly_Rate -> 18150
A11: Mounica Chadaram | B11: OnShore | C11: DEV | D11: 165 | E11: 10 | AA11: =SUM(E11:T11) -> 10 | AB11: =AA11*Hourly_Rate -> 1650
A12: Kris Wiklund | B12: OnShore | C12: DEV | D12: 165 | E12: 8 | F12: 16 | G12: 16 | H12: 16 | I12: 32 | J12: 8 | K12: 8 | AA12: =SUM(E12:T12) -> 104 | AB12: =AA12*Hourly_Rate -> 17160
A13: Naveem Jeevanandam | B13: OnShore | C13: DEV | D13: 165 | F13: 20 | G13: 20 | H13: 10 | I13: 10 | AA13: =SUM(E13:T13) -> 60
A14: Manuel Gahona | B14: OnShore | C14: DEV | D14: 165 | E14: 10 | F14: 10 | G14: 10 | H14: 10 | I14: 10 | J14: 10 | K14: 10 | L14: 10 | M14: 10 | N14: 10 | AA14: =SUM(E14:T14) -> 100 | AB14: =AA14*Hourly_Rate -> 16500
D15: Total OnShore Hours per Week | E15: =SUMIF($B$7:$B$14,"OnShore",E7:E14) -> 58 | F15: =SUMIF($B$7:$B$14,"OnShore",F7:F14) -> 98 | G15: =SUMIF($B$7:$B$14,"OnShore",G7:G14) -> 78 | H15: =SUMIF($B$7:$B$14,"OnShore",H7:H14) -> 68 | I15: =SUMIF($B$7:$B$14,"OnShore",I7:I14) -> 84 | J15: =SUMIF($B$7:$B$14,"OnShore",J7:J14) -> 50 | K15: =SUMIF($B$7:$B$14,"OnShore",K7:K14) -> 50 | L15: =SUMIF($B$7:$B$14,"OnShore",L7:L14) -> 42 | M15: =SUMIF($B$7:$B$10,"OnShore",M7:M10) -> 32 | N15: =SUMIF($B$7:$B$10,"OnShore",N7:N10) -> 32 | O15: =SUMIF($B$7:$B$10,"OnShore",O7:O10) -> 0 | P15: =SUMIF($B$7:$B$10,"OnShore",P7:P10) -> 0 | Q15: =SUMIF($B$7:$B$10,"OnShore",Q7:Q10) -> 0 | R15: =SUMIF($B$7:$B$10,"OnShore",R7:R10) -> 0 | S15: =SUMIF($B$7:$B$10,"OnShore",S7:S10) -> 0 | T15: =SUMIF($B$7:$B$10,"OnShore",T7:T10) -> 0 | ... Z15: =SUMIF($B$7:$B$10,"OnShore",Z7:Z10) -> 0 | AA15: =SUM(AA7:AA14) -> 612 | AB15: =AA15*Hourly_Rate -> 100980
D16: Total OnShore Hours per Week | E16: =SUMIF($B$7:$B$10,"OffShore",E7:E10) -> 0 | F16: =SUMIF($B$7:$B$10,"OffShore",F7:F10) -> 0 | G16: =SUMIF($B$7:$B$10,"OffShore",G7:G10) -> 0 | H16: =SUMIF($B$7:$B$10,"OffShore",H7:H10) -> 0 | I16: =SUMIF($B$7:$B$10,"OffShore",I7:I10) -> 0 | J16: =SUMIF($B$7:$B$10,"OffShore",J7:J10) -> 0 | K16: =SUMIF($B$7:$B$10,"OffShore",K7:K10) -> 0 | L16: =SUMIF($B$7:$B$10,"OffShore",L7:L10) -> 0 | ... Z16: =SUMIF($B$7:$B$10,"OffShore",Z7:Z10) -> 0 | AA16: =SUM(K16:N16) -> 0
D17: Total Resource Hours | E17: =SUM(E15:E16) -> 58 | F17: =SUM(F15:F16) -> 98 | G17: =SUM(G15:G16) -> 78 | H17: =SUM(H15:H16) -> 68 | I17: =SUM(I15:I16) -> 84 | J17: =SUM(J15:J16) -> 50 | K17: =SUM(K15:K16) -> 50 | L17: =SUM(L15:L16) -> 42 | ... Z17: =SUM(Z15:Z16) -> 0
D18: Total OnShore Expense | E18: =E15*Hourly_Rate -> 9570 | F18: =F15*Hourly_Rate -> 16170 | G18: =G15*Hourly_Rate -> 12870 | H18: =H15*Hourly_Rate -> 11220 | I18: =I15*Hourly_Rate -> 13860 | J18: =J15*Hourly_Rate -> 8250 | K18: =K15*Hourly_Rate -> 8250 | L18: =L15*Hourly_Rate -> 6930 | ... AA18: =AA15*Hourly_Rate -> 100980
D19: Total OffShore Expense | E19: =E16*135 -> 0 | F19: =F16*135 -> 0 | G19: =G16*135 -> 0 | H19: =H16*135 -> 0 | I19: =I16*135 -> 0 | J19: =J16*135 -> 0 | K19: =K16*135 -> 0 | L19: =L16*135 -> 0 | ... Z19: =Z16*135 -> 0 | AA19: =SUM(K19:N19) -> 0
D20: Total Expense | E20: =SUM(E18:E19) -> 9570 | F20: =SUM(F18:F19) -> 16170 | G20: =SUM(G18:G19) -> 12870 | H20: =SUM(H18:H19) -> 11220 | I20: =SUM(I18:I19) -> 13860 | J20: =SUM(J18:J19) -> 8250 | K20: =SUM(K18:K19) -> 8250 | L20: =SUM(L18:L19) -> 6930 | ... AA20: =SUM(AA18:AA19) -> 100980
S22: Available Budget as of 07/28 | AA22: 462.25
S23: CR | AA23: =AA15-AA22 -> 149.75 | AB23: Aprox
A25: Fill in Weeks
A26: Fill in Week Numbers
A27: Fill in Rates
A28: Fill in Types
A29: Fill in Names
A30: Use Copy/Insert Copied Columns to extend weeks
A31: Use Copy/Insert Copied Rows to Add more resources
A32: Add forecasted hours

Sheet EVM
E2: PERIOD
B3: ID | C3: DELIVERABLE TITLE | D3: Task Rate | E3: Total Budget | F3: ='Resource Plan - Approved'!E4 -> 43675 | G3: ='Resource Plan - Approved'!F4 -> 43682 | H3: ='Resource Plan - Approved'!G4 -> 43689 | I3: ='Resource Plan - Approved'!H4 -> 43696 | J3: ='Resource Plan - Approved'!I4 -> 43703 | K3: ='Resource Plan - Approved'!J4 -> 43710 | L3: ='Resource Plan - Approved'!K4 -> 43717 | M3: ='Resource Plan - Approved'!L4 -> 43724 | ... Y3: ='Resource Plan - Approved'!X4 -> 43808 | Z3: ='Resource Plan - Approved'!S4 -> 43773 | AA3: ='Resource Plan - Approved'!T4 -> 43780 | AB3: ='Resource Plan - Approved'!U4 -> 43787 | AC3: ='Resource Plan - Approved'!V4 -> 43794 | AD3: ='Resource Plan - Approved'!W4 -> 43801 | AE3: ='Resource Plan - Approved'!X4 -> 43808 | AF3: ='Resource Plan - Approved'!Y4 -> 43815 | AG3: ='Resource Plan - Approved'!Z4 -> 43822
F4: ='Resource Plan - Approved'!E5 -> DEV | G4: ='Resource Plan - Approved'!F5 -> DEV | H4: ='Resource Plan - Approved'!G5 -> UAT | I4: ='Resource Plan - Approved'!H5 -> UAT | J4: ='Resource Plan - Approved'!I5 -> TTT | K4: ='Resource Plan - Approved'!J5 -> REL | L4: ='Resource Plan - Approved'!K5 -> SS | M4: ='Resource Plan - Approved'!L5 -> SS | ... V4: ='Resource Plan - Approved'!U5 -> WK23 | W4: ='Resource Plan - Approved'!P5 -> PFS12 | X4: ='Resource Plan - Approved'!Q5 -> PFS13 | Y4: ='Resource Plan - Approved'!R5 -> PFS14 | Z4: ='Resource Plan - Approved'!S5 -> PFS15 | AA4: ='Resource Plan - Approved'!T5 -> WK22 | AB4: ='Resource Plan - Approved'!U5 -> WK23 | AC4: ='Resource Plan - Approved'!V5 -> WK24 | AD4: ='Resource Plan - Approved'!W5 -> WK25 | ... AG4: ='Resource Plan - Approved'!Z5 -> WK28
B5: 1 | C5: Project Management / Oversight | D5: 165 | E5: =SUM(F5:V5)*Hourly_Rate -> 19800 | F5: ='Resource Plan - Approved'!E7+'Resource Plan - Approved'!E8 -> 12 | G5: ='Resource Plan - Approved'!F7+'Resource Plan - Approved'!F8 -> 12 | H5: ='Resource Plan - Approved'!G7+'Resource Plan - Approved'!G8 -> 12 | I5: ='Resource Plan - Approved'!H7+'Resource Plan - Approved'!H8 -> 12 | J5: ='Resource Plan - Approved'!I7+'Resource Plan - Approved'!I8 -> 12 | K5: ='Resource Plan - Approved'!J7+'Resource Plan - Approved'!J8 -> 12 | L5: ='Resource Plan - Approved'!K7+'Resource Plan - Approved'!K8 -> 12 | M5: ='Resource Plan - Approved'!L7+'Resource Plan - Approved'!L8 -> 12 | ... O5: ='Resource Plan - Approved'!N7+'Resource Plan - Approved'!N8 -> 12 | AH5: =SUM(F5:T5) -> 120 | AI5: x
B6: =B5+1 -> 2 | C6: Functional Workstream - CRM Configuration | D6: 165 | E6: 16800 | F6: ='Resource Plan - Approved'!E9+'Resource Plan - Approved'!E11+'Resource Plan - Approved'!E13 -> 18 | G6: ='Resource Plan - Approved'!F9+'Resource Plan - Approved'!F11+'Resource Plan - Approved'!F13 -> 40 | H6: ='Resource Plan - Approved'!G9+'Resource Plan - Approved'!G11+'Resource Plan - Approved'!G13 -> 30 | I6: ='Resource Plan - Approved'!H9+'Resource Plan - Approved'!H11+'Resource Plan - Approved'!H13 -> 20 | J6: ='Resource Plan - Approved'!I9+'Resource Plan - Approved'!I11+'Resource Plan - Approved'!I13 -> 20 | K6: ='Resource Plan - Approved'!J9+'Resource Plan - Approved'!J11+'Resource Plan - Approved'!J13 -> 10 | L6: ='Resource Plan - Approved'!K9+'Resource Plan - Approved'!K11+'Resource Plan - Approved'!K13 -> 10 | M6: ='Resource Plan - Approved'!L9+'Resource Plan - Approved'!L11+'Resource Plan - Approved'!L13 -> 10 | ... O6: ='Resource Plan - Approved'!N9+'Resource Plan - Approved'!N11+'Resource Plan - Approved'!N13 -> 10 | AH6: =SUM(F6:T6) -> 178 | AI6: x
B7: =B6+1 -> 3 | C7: Portal Configuration | D7: 165 | E7: 45200 | F7: ='Resource Plan - Approved'!E10+'Resource Plan - Approved'!E14 -> 20 | G7: ='Resource Plan - Approved'!F10+'Resource Plan - Approved'!F14 -> 30 | H7: ='Resource Plan - Approved'!G10+'Resource Plan - Approved'!G14 -> 20 | I7: ='Resource Plan - Approved'!H10+'Resource Plan - Approved'!H14 -> 20 | J7: ='Resource Plan - Approved'!I10+'Resource Plan - Approved'!I14 -> 20 | K7: ='Resource Plan - Approved'!J10+'Resource Plan - Approved'!J14 -> 20 | L7: ='Resource Plan - Approved'!K10+'Resource Plan - Approved'!K14 -> 20 | M7: ='Resource Plan - Approved'!L10+'Resource Plan - Approved'!L14 -> 20 | ... O7: ='Resource Plan - Approved'!N10+'Resource Plan - Approved'!N14 -> 20 | AH7: =SUM(F7:T7) -> 210
B8: =B7+1 -> 4 | C8: Training | D8: 165 | E8: =SUM(F8:V8)*Hourly_Rate -> 17160 | F8: ='Resource Plan - Approved'!E12 -> 8 | G8: ='Resource Plan - Approved'!F12 -> 16 | H8: ='Resource Plan - Approved'!G12 -> 16 | I8: ='Resource Plan - Approved'!H12 -> 16 | J8: ='Resource Plan - Approved'!I12 -> 32 | K8: ='Resource Plan - Approved'!J12 -> 8 | L8: ='Resource Plan - Approved'!K12 -> 8 | M8: ='Resource Plan - Approved'!L12 | ... O8: ='Resource Plan - Approved'!N12 | AH8: =SUM(F8:T8) -> 104 | AI8: x
C9: TOTAL BUDGETED HOURS | E9: =SUM(F9:P9) -> 612 | F9: =SUM(F5:F8) -> 58 | G9: =SUM(G5:G8) -> 98 | H9: =SUM(H5:H8) -> 78 | I9: =SUM(I5:I8) -> 68 | J9: =SUM(J5:J8) -> 84 | K9: =SUM(K5:K8) -> 50 | L9: =SUM(L5:L8) -> 50 | M9: =SUM(M5:M8) -> 42 | ... AG9: =SUM(AG5:AG8) -> 0 | AH9: =SUM(F9:T9) -> 612
B10: BAC | C10: TOTAL BUDGETED COST | E10: =E9*Hourly_Rate -> 100980 | F10: =(SUM(F5:F8)*(Hourly_Rate)) -> 9570 | G10: =(SUM(G5:G8)*(Hourly_Rate)) -> 16170 | H10: =(SUM(H5:H8)*(Hourly_Rate)) -> 12870 | I10: =(SUM(I5:I8)*(Hourly_Rate)) -> 11220 | J10: =(SUM(J5:J8)*(Hourly_Rate)) -> 13860 | K10: =(SUM(K5:K8)*(Hourly_Rate)) -> 8250 | L10: =(SUM(L5:L8)*(Hourly_Rate)) -> 8250 | M10: =(SUM(M5:M8)*(Hourly_Rate)) -> 6930 | N10: =SUM(N9*165) -> 6930 | O10: =SUM(O9*165) -> 6930 | P10: =SUM(P9*165) -> 0 | Q10: =SUM(Q9*165) -> 0 | R10: =SUM(R9*165) -> 0 | S10: =SUM(S9*165) -> 0 | T10: =SUM(T9*165) -> 0 | U10: =SUM(U9*165) -> 0 | ... AG10: =SUM(AG9*165) -> 0
B11: PV | C11: CUMLATIVE PLANNED VALUE | F11: =F10 -> 9570 | G11: =F11+G10 -> 25740 | H11: =G11+H10 -> 38610 | I11: =H11+I10 -> 49830 | J11: =I11+J10 -> 63690 | K11: =J11+K10 -> 71940 | L11: =K11+L10 -> 80190 | M11: =L11+M10 -> 87120 | N11: =M11+N10 -> 94050 | ... AG11: =AF11+AG10 -> 100980
B13: ACTUAL COST
D14: WORK ENDING | F14: =G3-1 -> 43681 | G14: =F14+7 -> 43688 | H14: =G14+7 -> 43695 | I14: =H14+7 -> 43702 | J14: =I14+7 -> 43709 | K14: =J14+7 -> 43716 | L14: =K14+7 -> 43723 | M14: =L14+7 -> 43730 | N14: =M14+7 -> 43737 | ... W14: =V14+7 -> 43800 | X14: =X3+6 -> 43807 | Y14: =Y3+6 -> 43814 | Z14: =Z3+6 -> 43779 | AA14: =AA3+6 -> 43786 | AB14: =AB3+6 -> 43793 | AC14: =AC3+6 -> 43800 | AD14: =AD3+6 -> 43807 | AE14: =AE3+6 -> 43814 | ... AG14: =AG3+6 -> 43828
D15: (ONSHORE) ACTUAL HOURS | E15: =SUM(F15:U15) -> 177.5 | F15: =SUMIFS(ACTUALS!$K:$K,ACTUALS!$A:$A, "Billable",ACTUALS!$L:$L,F14) -> 102 | G15: =SUMIFS(ACTUALS!$K:$K,ACTUALS!$A:$A, "Billable",ACTUALS!$L:$L,G14) -> 75.5 | H15: =SUMIFS(ACTUALS!$K:$K,ACTUALS!$A:$A, "Billable",ACTUALS!$L:$L,H14) -> 0 | I15: =SUMIFS(ACTUALS!$K:$K,ACTUALS!$A:$A, "Billable",ACTUALS!$L:$L,I14) -> 0 | J15: =SUMIFS(ACTUALS!$K:$K,ACTUALS!$A:$A, "Billable",ACTUALS!$L:$L,J14) -> 0 | K15: =SUMIFS(ACTUALS!$K:$K,ACTUALS!$A:$A, "Billable",ACTUALS!$L:$L,K14) -> 0 | L15: =SUMIFS(ACTUALS!$K:$K,ACTUALS!$A:$A, "Billable",ACTUALS!$L:$L,L14) -> 0 | M15: =SUMIFS(ACTUALS!$K:$K,ACTUALS!$A:$A, "Billable",ACTUALS!$L:$L,M14) -> 0 | ... AG15: =SUMIFS(ACTUALS!$K:$K,ACTUALS!$A:$A, "Billable",ACTUALS!$L:$L,AG14) -> 0
D16: (ONSHORE) ACTUAL COST | E16: =SUM(F16:U16) -> 29287.5 | F16: =F15*165 -> 16830 | G16: =G15*165 -> 12457.5 | H16: =H15*165 -> 0 | I16: =I15*165 -> 0 | J16: =J15*165 -> 0 | K16: =K15*165 -> 0 | L16: =L15*165 -> 0 | M16: =M15*165 -> 0 | ... AG16: =AG15*165 -> 0
D17: (OFFSHORE) ACTUAL HOURS | E17: =SUM(F17:U17) -> 0 | F17: =SUMIFS(ACTUALS!$K:$K,ACTUALS!$A:$A, "Billable",ACTUALS!$M:$M,"OffShore",ACTUALS!$L:$L,F14) -> 0 | G17: =SUMIFS(ACTUALS!$K:$K,ACTUALS!$A:$A, "Billable",ACTUALS!$M:$M,"OffShore",ACTUALS!$L:$L,G14) -> 0 | H17: =SUMIFS(ACTUALS!$K:$K,ACTUALS!$A:$A, "Billable",ACTUALS!$M:$M,"OffShore",ACTUALS!$L:$L,H14) -> 0 | I17: =SUMIFS(ACTUALS!$K:$K,ACTUALS!$A:$A, "Billable",ACTUALS!$M:$M,"OffShore",ACTUALS!$L:$L,I14) -> 0 | J17: =SUMIFS(ACTUALS!$K:$K,ACTUALS!$A:$A, "Billable",ACTUALS!$M:$M,"OffShore",ACTUALS!$L:$L,J14) -> 0 | K17: =SUMIFS(ACTUALS!$K:$K,ACTUALS!$A:$A, "Billable",ACTUALS!$M:$M,"OffShore",ACTUALS!$L:$L,K14) -> 0 | L17: =SUMIFS(ACTUALS!$K:$K,ACTUALS!$A:$A, "Billable",ACTUALS!$M:$M,"OffShore",ACTUALS!$L:$L,L14) -> 0 | M17: =SUMIFS(ACTUALS!$K:$K,ACTUALS!$A:$A, "Billable",ACTUALS!$M:$M,"OffShore",ACTUALS!$L:$L,M14) -> 0 | ... AG17: =SUMIFS(ACTUALS!$K:$K,ACTUALS!$A:$A, "Billable",ACTUALS!$M:$M,"OffShore",ACTUALS!$L:$L,AG14) -> 0
D18: (OFFSHORE) ACTUAL COST | E18: =SUM(F18:U18) -> 0 | F18: =F17*135 -> 0 | G18: =G17*135 -> 0 | H18: =H17*135 -> 0 | I18: =I17*135 -> 0 | J18: =J17*135 -> 0 | K18: =K17*135 -> 0 | L18: =L17*135 -> 0 | M18: =M17*135 -> 0 | ... AG18: =AG17*135 -> 0
B19: AC | D19: CUMULATIVE ACTUAL COST | F19: =F16+F18 -> 16830 | G19: =F19+G16+G18 -> 29287.5 | H19: =G19+H16+H18 -> 29287.5 | I19: =H19+I16+I18 -> 29287.5 | J19: =I19+J16+J18 -> 29287.5 | K19: =J19+K16+K18 -> 29287.5 | L19: =K19+L16+L18 -> 29287.5 | M19: =L19+M16+M18 -> 29287.5 | N19: =M19+N16+N18 -> 29287.5 | ... AG19: =AF19+AG16+AG18 -> 29287.5
B21: EARNED VALUE
B22: EV | D22: CUMULATIVE EARNED VALUE | F22: ='EV WORKSHEET'!E9 -> 6520 | G22: ='EV WORKSHEET'!F9 -> 8264 | H22: ='EV WORKSHEET'!G9 -> 8220 | I22: ='EV WORKSHEET'!H9 -> 1680 | J22: ='EV WORKSHEET'!I9 -> 268800 | K22: ='EV WORKSHEET'!J9 -> 0 | L22: ='EV WORKSHEET'!K9 -> 0 | M22: ='EV WORKSHEET'!L9 -> 0 | ... T22: ='EV WORKSHEET'!S9 -> 0 | U22: ='EV WORKSHEET'!Q9 -> 0 | V22: ='EV WORKSHEET'!R9 -> 0 | W22: ='EV WORKSHEET'!S9 -> 0 | X22: ='EV WORKSHEET'!T9 -> 0 | Y22: ='EV WORKSHEET'!U9 -> 0 | Z22: ='EV WORKSHEET'!V9 -> 0 | AA22: ='EV WORKSHEET'!W9 -> 0 | AB22: ='EV WORKSHEET'!X9 -> 0 | ... AF22: ='EV WORKSHEET'!AB9 -> 0 | AG22: ='EV WORKSHEET'!AD9
B24: PROJECT PERFORMANCE METRICS
B25: CV | D25: COST VARIANCE | E25: ( EV – AC ) | F25: =F22-F19 -> -10310 | G25: =G22-G19 -> -21023.5 | H25: =H22-H19 -> -21067.5 | I25: =I22-I19 -> -27607.5 | J25: =J22-J19 -> 239512.5 | K25: =K22-K19 -> -29287.5 | L25: =L22-L19 -> -29287.5 | M25: =M22-M19 -> -29287.5 | ... AG25: =AG22-AG19 -> -29287.5
B26: SV | D26: SCHEDULE VARIANCE | E26: ( EV – PV ) | F26: =F22-F11 -> -3050 | G26: =G22-G11 -> -17476 | H26: =H22-H11 -> -30390 | I26: =I22-I11 -> -48150 | J26: =J22-J11 -> 205110 | K26: =K22-K11 -> -71940 | L26: =L22-L11 -> -80190 | M26: =M22-M11 -> -87120 | ... AG26: =AG22-AG11 -> -100980
B27: CPI | D27: COST PERFORMANCE INDEX | E27: ( EV / AC ) | F27: =F22/F19 -> 0.38740345 | G27: =G22/G19 -> 0.28216816 | H27: =H22/H19 -> 0.28066581 | I27: =I22/I19 -> 0.057362356 | J27: =J22/J19 -> 9.177977 | K27: =K22/K19 -> 0 | L27: =L22/L19 -> 0 | M27: =M22/M19 -> 0 | ... AG27: =AG22/AG19 -> 0
B28: SPI | D28: SCHEDULE PERFORMANCE INDEX | E28: ( EV / PV ) | F28: =F22/F11 -> 0.68129572 | G28: =G22/G11 -> 0.32105672 | H28: =H22/H11 -> 0.21289821 | I28: =I22/I11 -> 0.03371463 | J28: =J22/J11 -> 4.2204428 | K28: =K22/K11 -> 0 | L28: =L22/L11 -> 0 | M28: =M22/M11 -> 0 | ... AG28: =AG22/AG11 -> 0
B29: EAC | D29: ESTIMATED COST AT COMPLETION | F29: =$E$10/F27 -> 260658.5 | G29: =$E$10/G27 -> 357871.7 | H29: =$E$10/H27 -> 359787.32 | I29: =$E$10/I27 -> 1760387.9 | J29: =$E$10/J27 -> 11002.425 | K29: =$E$10/K27 -> #DIV/0! | L29: =$E$10/L27 -> #DIV/0! | M29: =$E$10/M27 -> #DIV/0! | ... AG29: =$E$10/AG27 -> #DIV/0!
C31: A cost performance index higher than 1.0 indicates that the project is costing less than expected; one that’s less than 1.0 indicates a project that’s costing more than expected.
C32: A schedule performance index higher than 1.0 indicates that the project is ahead of schedule; one that’s below 1.0 indicates that it’s running behind schedule.
AI33: =SUM(F9:P9)-SUM(F15:P15) -> 434.5
B35: Setup:
B36: Fill in Deliverable Titles
B37: Fill in Rates
B38: Use Copy/Insert Copied Columns to extend weeks
B39: Use Copy/Insert Copied Rows to Deliverable Titles
B40: Plot Forecasted hours against Deliverables
B41: Confirm Total Budgeted hours = Total Resource Weekly Totals
B43: Weekly:
B44: ** Relies on Weekly Actuals to be updated first
B45: Copy EVM calculations from previous week to current week
B46: Update Chart Data

Sheet EV WORKSHEET
E2: PERIOD
B3: ID | C3: DELIVERABLE TITLE | D3: Total Budget | E3: =EVM!F3 -> 43675 | F3: =EVM!G3 -> 43682 | G3: =EVM!H3 -> 43689 | H3: =EVM!I3 -> 43696 | I3: =EVM!J3 -> 43703 | J3: =EVM!K3 -> 43710 | K3: =EVM!L3 -> 43717 | L3: =EVM!M3 -> 43724 | ... S3: =EVM!T3 -> 43773 | T3: =EVM!X3 -> 43801 | U3: =EVM!Y3 -> 43808 | V3: =EVM!Z3 -> 43773 | W3: =EVM!AA3 -> 43780 | X3: =EVM!AB3 -> 43787 | Y3: =EVM!AC3 -> 43794 | Z3: =EVM!AD3 -> 43801 | AA3: =EVM!AE3 -> 43808 | ... AC3: =EVM!AG3 -> 43822
E4: =EVM!F4 -> DEV | F4: =EVM!G4 -> DEV | G4: =EVM!H4 -> UAT | H4: =EVM!I4 -> UAT | I4: =EVM!J4 -> TTT | J4: =EVM!K4 -> REL | K4: =EVM!L4 -> SS | L4: =EVM!M4 -> SS | ... S4: =EVM!T4 -> PFS15 | T4: =EVM!X4 -> PFS13 | U4: =EVM!Y4 -> PFS14 | V4: =EVM!Z4 -> PFS15 | W4: =EVM!AA4 -> WK22 | X4: =EVM!AB4 -> WK23 | Y4: =EVM!AC4 -> WK24 | Z4: =EVM!AD4 -> WK25 | AA4: =EVM!AE4 -> WK26 | ... AC4: =EVM!AG4 -> WK28
B5: =EVM!B5 -> 1 | C5: =EVM!C5 -> Project Management / Oversight | D5: 12800 | E5: 0.1 | F5: 0.18
B6: =EVM!B6 -> 2 | C6: =EVM!C6 -> Functional Workstream - CRM Configuration | D6: 16800 | E6: 0 | F6: 0 | G6: 0 | H6: 0.1 | I6: 16
B7: =EVM!B7 -> 3 | C7: =EVM!C7 -> Portal Configuration | D7: =EVM!E7 -> 45200 | E7: 0.1 | F7: 0.1 | G7: 0.15
B8: =EVM!B8 -> 4 | C8: =EVM!C8 -> Training | D8: 14400 | E8: 0.05 | F8: 0.1 | G8: 0.1
B9: EV | C9: CUMULATIVE EARNED VALUE | D9: =SUM(D5:D8) -> 89200 | E9: =SUMPRODUCT(E5:E8,$D$5:$D$8) -> 6520 | F9: =SUMPRODUCT(F5:F8,$D$5:$D$8) -> 8264 | G9: =SUMPRODUCT(G5:G8,$D$5:$D$8) -> 8220 | H9: =SUMPRODUCT(H5:H8,$D$5:$D$8) -> 1680 | I9: =SUMPRODUCT(I5:I8,$D$5:$D$8) -> 268800 | J9: =SUMPRODUCT(J5:J8,$D$5:$D$8) -> 0 | K9: =SUMPRODUCT(K5:K8,$D$5:$D$8) -> 0 | L9: =SUMPRODUCT(L5:L8,$D$5:$D$8) -> 0 | ... AC9: =SUMPRODUCT(AC5:AC8,$D$5:$D$8) -> 0
C13: Setup: | K13: 9 | L13: 0.5
C14: Confirm Titles, Weeks, Budget colums/rows copied correctly | K14: 1 | L14: =K14*L13/K13 -> 0.055555556
C15: Use Copy/Insert Copied Columns to extend weeks
C16: Use Copy/Insert Copied Rows to Deliverable Titles
C18: Weekly:
C19: Update % Complete for the week per Deliverable | I19: Functional | J19: Wkst1 | K19: =L14/FW -> 0.0079365079
C20: ** Relies on Project Plan to be updated | I20: 7 | J20: Wkst2 | K20: 0.010204082
J21: Wkst3 | K21: 0.010204082
J22: Wkst4 | K22: 0.010204082 | AD22: 100
J23: Wkst5 | K23: 0.010204082
J24: Wkst6 | K24: 0.010204082
J25: Wkst7 | K25: 0.010204082

Sheet ACTUALS
A1: Type | B1: Employee | C1: Task | D1: Mon | E1: Tue | F1: Wed | G1: Thu | H1: Fri | I1: Sat | J1: Sun | K1: Total | L1: Week Ending | M1: Type | N1: Rate
A2: Billable | B2: Agustin Galindo | K2: 5 | L2: 43681 | M2: OnShore | N2: 165
A3: Billable | B3: Mounica Chadaram | K3: 40 | L3: 43681 | M3: OnShore | N3: 165
A4: Billable | B4: Scott Soulages | K4: 26 | L4: 43681 | M4: OnShore | N4: 165
A5: Billable | B5: Vladimir Belomestnov | K5: 31 | L5: 43681 | M5: OnShore | N5: 165
A6: Billable | B6: Agustin Galindo | K6: 7 | L6: 43688 | M6: OnShore | N6: 165
A7: Billable | B7: Kris Wilklund | K7: 16 | L7: 43688 | M7: OnShore | N7: 165
A8: Billable | B8: Naveen Kumar Jeevanandam | K8: 12 | L8: 43688 | M8: OnShore | N8: 165
A9: Billable | B9: Scott Soulages | K9: 11 | L9: 43688 | M9: OnShore | N9: 165
A10: Billable | B10: Scott Soulages | K10: 10 | L10: 43688 | M10: OnShore | N10: 165
A11: Billable | B11: Scott Soulages | K11: 1.5 | L11: 43688 | M11: OnShore | N11: 165
A12: Billable | B12: Scott Soulages | K12: 3.5 | L12: 43688 | M12: OnShore | N12: 165
A13: Billable | B13: Scott Soulages | K13: 0.5 | L13: 43688 | M13: OnShore | N13: 165
A14: Billable | B14: Vladimir Belomestnov | K14: 14 | L14: 43688 | M14: OnShore | N14: 165
A15: Billable | M15: OnShore | N15: 165
A16: Billable | M16: OnShore | N16: 165
A17: Billable | M17: OnShore | N17: 165
A18: Billable | M18: OnShore | N18: 165
A19: Billable | M19: OnShore | N19: 165
A20: Billable | M20: OnShore | N20: 165
A21: Billable | M21: OnShore | N21: 165
A22: Billable | M22: OnShore | N22: 165
A23: Billable | M23: OnShore | N23: 165
A24: Billable | M24: OnShore | N24: 165
A25: Billable | M25: OnShore | N25: 165
A26: Billable | M26: OnShore | N26: 165
A27: Billable
A28: Billable
A29: Billable
A30: Billable
A31: Billable
A32: Billable
A33: Billable
A34: Billable
A35: Billable
A36: Billable
A37: Billable
A38: Billable | M38: OnShore | N38: =(ACTUALS!Hourly_Rate) -> 165
A39: Billable | M39: OnShore | N39: =(ACTUALS!Hourly_Rate) -> 165
A40: Billable | M40: OnShore | N40: =(ACTUALS!Hourly_Rate) -> 165
...
